Workbook

Sheet Sheet1
A1: Subject Area 2022-23 | B1: Teacher | C1: A | D1: B | E1: C | F1: D | G1: E | H1: A | I1: B | J1: C | K1: D | L1: E
A2: Math (5.0) | B2: Gadsby 219 | C2: Preps | D2: ENTR2S-01 | E2: MATR1F-E1 9-01+9-04 | F2: ESMR2S-02 | G2: ESMR3S-02 | H2: Preps | I2: ESMR2S-04 | J2: MATR1F-E1 9-01+9-04 | K2: SCIR1F-04 | L2: BCOR3S-01
A3: SSC (2.0) | B3: Church 210 | C3: SSC | D3: Preps | E3: SSC | F3: SSC* | G3: SSC | H3: SSC | I3: Preps | J3: SSC | K3: SSC* | L3: SSC
B4: Buller 210 | C4: SSC | D4: Preps | E4: SSC | F4: SSC | G4: SSC | H4: SSC | I4: Preps | J4: SSC | K4: SSC | L4: SSC
B5: Ward 212 | C5: PCMR3S-01 | D5: ESMR2S-01 | E5: Preps | F5: MATX1F-E2 9-02, 03,05 | G5: MATR1F-AI | H5: ESMR 3S-03 | I5: IAPR2S-02 | J5: ADMR4S-01 CALR4S-01 | K5: Preps | L5: MATR1F-E2 902,03,05
B6: Pisa 216 | C6: ESMR3S-01 | D6: IAPR2S-01 | E6: ESMR4S-01 | F6: MATX1F-P2 9-02,03,05 | G6: Preps | H6: PCMR 3S-02 | I6: ESMR3S-04 | J6: ESMR2S-03 | K6: Preps | L6: MATR1F-P2 902,03,05
B7: Zurzolo 106 | C7: PCMR 4S-01 1st Semester | D7: Preps | E7: MATR1F-P1 9-01+9-04 | F7: PHYR3S-01 | G7: COSR2S-01 | H7: PHYR4S-01 | I7: ESMR4S-03* | J7: MATR1F-P1 9-01+9-04 | K7: Preps | L7: COSR3,4S-02
B8: McLarty 220 (Zeif) | C8: ESMR 4S-02 | D8: APMR3S-01 | E8: ESMR2-4S R1 | F8: MATX1F- P3 9-02,03,05 | G8: Preps | H8: ESMR2-4S R2 | I8: PCMR4S-01 2nd Semester | J8: APMR4S-01 | K8: Preps | L8: MATR1F P3 9-02,03,05
A9: Science -3.0 | B9: Samuels 112 | C9: SCIR2F-02 | D9: BIOR3S-01 | E9: BIOR4S-01 | F9: Preps | G9: SCIR1F-05 | H9: Preps | I9: BIOR3S-02 | J9: BIOR4S-02 | K9: SCIR1F-03 | L9: SCIR1F-01
B10: Nguyen 118 | C10: CHER4S-01 | D10: SCIR2F-01 | E10: CHER3S-01* | F10: SCIE 2F-01* | G10: Preps* | H10: Preps | I10: SCIR2F-03 | J10: CHER3S-02 | K10: CHER4S-02 | L10: SCIR2F-04
B11: Desautels 228/118 | C11: ICTAF -01/ DPHR3S-01 WDHR3S-01 | D11: Comp 7 & 8 | E11: LWER1S-05 | F11: Preps/Web site | G11: DFHR2S-01 DPHR2S-01 | H11: ICTA1F-02 DPHR3S-02 WDHR3S-02 | I11: Comp 7 & 8 | J11: Preps/Website | K11: SCIR1F-02 | L11: DFHR2S-02 DPHR2S-02
A12: ELA/SS – 7.0 | B12: Robbie 229 | C12: Preps | D12: ENGC4S-01 | E12: ENGC3S-02 | F12: ENGR1F-01 | G12: ENGR1X-03 | H12: ENGC 3S-03 | I12: ENGC4S-03 | J12: ENGR1F-03 | K12: ENGR1F-01 | L12: Preps
B13: Costa 217 | C13: Preps | D13: HISR3F-01 | E13: ENGR2F-01 | F13: GEOR2F- 02 | G13: GLIR 4S-01 | H13: HISR3F-03 | I13: ENGR 2F-03 | J13: ENGC3S-04 | K13: ABSR4S-01 | L13: Preps
B14: Parisien 227 | C14: ENGC3S-01 | D14: ENGC4S-02 | E14: ENGR1F-02 | F14: Preps | G14: ENGR1F-04 | H14: ENGC4S-04 | I14: CMHR 4S-01 | J14: ENGR1F-02 | K14: Preps | L14: ENGR1F-04
B15: Willow 221 | C15: ENGR2F-02 | D15: LWER 1S-04 | E15: RITR 2-4G-01 | F15: DAMR 2S, 3S,4S-01 | G15: Preps | H15: Preps | I15: LWER 1S-02 | J15: ENGR 2F- 04 | K15: DTHR 2S,3S,4S-01 | L15: ENGT4S-01
B16: Grunewald 215 | C16: HISR 3F-02 | D16: ENGR1F-05 | E16: ENG1F-AI | F16: Preps | G16: SOSR1F-02 | H16: LAWR 4S-01 | I16: ENGR1F-05 | J16: HISR 3F-04 | K16: SOSR1F-05 | L16: Preps
B17: Winger 135 | C17: TTBR4S-01 RTBR3S-01 CRPR2S-01 | D17: GEOR2F-01 | E17: PSYR4S-01 | F17: Preps | G17: CATT2-4S zz | H17: TTBR4S-02 RTBR3S-02 CRPR2S-02 | I17: GEOR2F-04 | J17: PSYR4S-02 | K17: Preps | L17: CATT 2-4S zz
B18: Carvalho 222 | C18: Preps | D18: LWER1S-03 | E18: SOSR1F-03 | F18: SOSR1F-04 | G18: SOSR1F-01 | H18: LWPR2S-01 LWBR3S-01 | I18: LWER1S-01 | J18: GEOR 2F-03 | K18: Preps | L18: GEOR2F-05* (INSR 3S-01 CTSR 4S-01)
A19: LAL -1 | B19: LAL 234 | E19: ENBU 1,2,3G EANU 4G | J19: ENBU 1,2,3G EANU 4G
A20: Subject Area | B20: Teacher | C20: A | D20: B | E20: C | F20: D | G20: E | H20: A | I20: B | J20: C | K20: D | L20: E
D21: INSR3S CTSR4S ???? | I21: INSR3S CTSR4S ????
A22: Phys Ed (4) | B22: Baker Sr. Gym & 223 | C22: PHER2F 01-02 | D22: PHER1G-01 | F22: PHER3F-03 | G22: PHER3F-03 | H22: PHER2F 03-04 | I22: PHER1G-03 | K22: PHER3F-03 | L22: PHER3F-04
B23: Stewart Sr. Gym &135 | C23: PHER 2F - | D23: PHER 1G-02 | F23: PHER4F-01 | G23: PHER3F-02 | H23: PHER2F- | I23: PHER1G-04 | K23: PHER3F--03 | L23: PHER3F-04
B24: Kubas* Sr. Gym & 223 | E24: Spec Ed PE PHER 1M- | J24: PHER1G-05
A25: The Arts –(2.5) | B25: Boyko* 159 | C25: VAHB1S-01/02 | D25: 7&8 Art | E25: VIAR2S-01 | F25: VIAR3S/4S-01 | G25: Preps | H25: VAHB1S-03/04 | I25: 7&8 Art | J25: VIAR3S/4S-02 | K25: VIAR2S-02 | L25: Preps
B26: Boville* 110 D-2,4,6 | C26: Noon hour Choir zz /MGUH 1S | D26: /MGUH 2-4S 01 MPIH 2-4S-01 .5 | E26: (/DMTR1S-4S-01) OUT (Noon Hour Choir | F26: (/MCCR2-4S-01) | G26: Preps + TM | H26: DAHB1S (4A) D1,4,6 | I26: MGUH 2-4S 02 (2A) MPIH2-4S-02 (2A) / | J26: MCCH 2-4S (2A)XXXXXXX | K26: /MCCR2-4S-01 | L26: Noon hour Choir zz
B27: Sawatzky* 155 | C27: MCBR1S-01/ Sr. Jazz Band zz | D27: 7 & 8 Band | E27: 7&8 Fl Band/ Int. Jazz Band zz | F27: Preps | G27: MCBR2-4S-01/ Jr. Jazz Band zz | H27: MCBR1S-01/ Sr. Jazz Band zz | I27: 7 & 8 Band | J27: 7&8 Fl. Band/ Int. Jazz Band zz | K27: Preps | L27: MCBR2-4S-01/ Jr. Jazz Band) zz
A28: IA/HE (5) | B28: Brugger* | C28: TDHR1S-01/ | D28: PRAY 7/ PRAY8 | E28: HOER2-4G-01* | F28: TADR2-4S-01 | G28: FSTR2-4S-01 | H28: TDHR1S-02/ | I28: PRAY 7/ PRAY8 | J28: /HOER2-4G01* | K28: TADR2-4S-02 | L28: FSTR2-4S-02
B29: Didych* | C29: ELHR1G-01/PMHR1G-01 | D29: PRAY 7/ PRAY8 | E29: Preps | F29: ELER2,3G,4S-01 | G29: POMR2,3G,4S -01 | H29: PMHR1G-02/03 | I29: PRAY 7/ PRAY8 | J29: Preps | K29: POMR 2,3G,4S-02 | L29: METR2,3G-4S -01
B30: Gomez* Changed FNUR 2G & 3G,4S | C30: FOHR1S-01/02 | D30: PRAY 7/ PRAY8 | E30: Preps | F30: FNUR2S-01 | G30: FNUR3G,4S-01 | H30: FOHR1S -03/04 | I30: PRAY 7/ PRAY8 | J30: Preps | K30: FNUR3G,4S-02 | L30: FNUR2S-02
B31: Ostrowski* | C31: WOHR1G-01/ELHR1G 02 | D31: PRAY 7/ PRAY8 | E31: Preps | F31: WOOR2G-01 | G31: WOOR3G,4S-01 | H31: WOHR1G-02/03 | I31: PRAY 7/ PRAY8 | J31: Preps/ | K31: WOOR 3G,4S-02 | L31: WOOR2G-02
B32: Reis* | C32: GRHR 1G-01/02 | D32: PRAY 7/ PRAY8 | E32: Preps | F32: GRAR3G,4S - 01 | G32: GRAR2G-01 | H32: GRHR1G-03/04 | I32: PRAY 7/ PRAY8 | J32: Preps/ | K32: GRAR2G-02 | L32: GRAR3G,4S-02
A33: Subject Area | B33: Teacher | C33: A | D33: B | E33: C | F33: D | G33: E | H33: A | I33: B | J33: C | K33: D | L33: E
A34: Computers | B34: Desautels Zurzolo | C34: ICTA1F-01 | D34: PRAY 7/ PRAY8 | E34: Preps | G34: COSR2S-01 | H34: ICTA1F-02 | I34: PRAY 7/ PRAY8 | L34: COSR3-4S-01
A35: Business | C35: TTBR4S-01 RTPR3S-01 CRPR2S-01 | D35: ENTR2S-01 | F35: CATT | H35: TTBR4S-02 RTPR3S-02 CRPR2S-02 | K35: CATT | L35: BCOR3S-01
A36: Gr. 7 ELA/SS – 4 | B36: ? | C36: Sinclair | D36: Jobin | E36: ?
A37: Gr.8 Math/Sci - 4 | B37: ? | C37: Sanburn | D37: Myskiw | E37: Orysiuk
A38: Flex - 2 | B38: Bailey | C38: Forslund
A39: Guid - 3 | B39: Davies Alford Schwab
A40: OC -1 | B40: Bruneau
...

Sheet Potential 1
C1: =SUM(C2:G2) -> 4 | H1: =SUM(H2:L2) -> 4
B2: counts | C2: =COUNTIF(C5:C48,"*"&$C$3&"*") -> 0 | D2: =COUNTIF(D5:D48,"*"&$C$3&"*") -> 1 | E2: =COUNTIF(E5:E48,"*"&$C$3&"*") -> 1 | F2: =COUNTIF(F5:F48,"*"&$C$3&"*") -> 1 | G2: =COUNTIF(G5:G48,"*"&$C$3&"*") -> 1 | H2: =COUNTIF(H5:H48,"*"&$C$3&"*") -> 0 | I2: =COUNTIF(I5:I48,"*"&$C$3&"*") -> 1 | J2: =COUNTIF(J5:J48,"*"&$C$3&"*") -> 1 | ... L2: =COUNTIF(L5:L48,"*"&$C$3&"*") -> 1
B3: Highlight | C3: 9d
A4: Subject Area 2b2-23 | B4: Teacher | C4: A | D4: B | E4: C | F4: D | G4: E | H4: A | I4: B | J4: C | K4: D | L4: E
A5: Math (5.0) | B5: Gadsby 219 | C5: Preps | D5: SCIR1F-9d | E5: ENTR2S-a | F5: ESMR2S-b | G5: ESMR3S-b | H5: Preps | I5: ESMR2S-d | J5: SCIR1F-9b | L5: BCOR3S-a
A6: SSC (2.0) | B6: Church 210 | C6: SSC | D6: Preps | E6: SSC | F6: SSC* | G6: SSC | H6: SSC | I6: Preps | J6: SSC | K6: SSC* | L6: SSC
B7: Buller 210 | C7: SSC | D7: Preps | E7: SSC | F7: SSC | G7: SSC | H7: SSC | I7: Preps | J7: SSC | K7: SSC | L7: SSC
B8: Ward 212 | C8: PCMR3S-a | D8: ESMR2S-a | E8: MATR1F-9a | F8: Preps | G8: MATR1F-9b | H8: ESMR 3S-c | I8: IAPR2S-b | J8: MATR1F-9a | K8: Preps | L8: MATR1F-9b
B9: Pisa 216 | C9: ESMR3S-a | D9: IAPR2S-a | E9: ESMR4S-a | F9: Preps | G9: MATR1F-9c | H9: PCMR 3S-b | I9: ESMR3S-d | J9: ESMR2S-c | K9: Preps | L9: MATR1F-9c
B10: Zurzolo 106 | C10: PCMR 4S-a first Semester | D10: Preps | E10: MATR1F-9e | F10: PHYR3S-a | G10: COSR2S-a | H10: PHYR4S-a | I10: ESMR4S-c* | J10: MATR1F-9e | K10: Preps | L10: COSR3,4S-b
B11: McLarty 220 (Zeif) | C11: ESMR 4S-b | D11: APMR3S-a | E11: ESMR2-4S Multi | F11: Preps | G11: MATR1F-9d | H11: ESMR2-4S R2 | I11: PCMR4S-a 2nd Semester | J11: APMR4S-a | K11: Preps | L11: MATR1F-9d | M11: ZZ--ADMR4S-a CALR4S-a
A12: Science -3.0 | B12: Samuels 112 | C12: SCIR2F-b | D12: BIOR3S-a | E12: BIOR4S-a | F12: SCIR1F-9c | G12: Preps | H12: WPR2S-a LWBR3S-a | I12: BIOR3S-b | J12: BIOR4S-b | K12: LWER1S-9c | L12: Preps
B13: Nguyen 118 | C13: CHER4S-a | D13: SCIR2F-a | E13: CHER3S-a* | F13: SCIE 2F-a* | G13: Preps | H13: Preps | I13: SCIR2F-c | J13: CHER3S-b | K13: CHER4S-b | L13: SCIR2F-d
B14: Desautels 228/118 | C14: ICTA1F -a/ DPHR3S-a WDHR3S-a | D14: Comp 7 & 8 | E14: LWER1S-9b | F14: Website/preps | G14: DFHR2S-a DPHR2S-a | H14: ICTA1F-b DPHR3S-b WDHR3S-b | I14: Comp 7 & 8 | J14: GEOR 2F-c | K14: Website/preps | L14: DFHR2S-b DPHR2S-b
B15: Sanburn | G15: SCIR1F-9a | L15: LWER1S-9a
B16: Myskiw | F16: MATR1F-9Aim | K16: SCIR1F - Repeat
A17: ELA/SS – 7.0 | B17: Costa 217 | C17: Preps | D17: ENGC4S-a | E17: ENGR2F-a | F17: GEOR2F- b | G17: GLIR 4S-a | H17: ENGC 3S-c | I17: ENGR 2F-c | J17: ENGC3S-d | K17: ABSR4S-a | L17: Preps
B18: Parisien 227 | C18: ENGC3S-a | D18: ENGC4S-b | E18: ENGR1F-9c | F18: Preps | G18: CMHR 4S-a | H18: ENGC4S-d | I18: ENGC4S-c | J18: ENGR1F-9c | K18: Preps | L18: ENGT4S-a
B19: Willow 221 | C19: ENGR2F-b | D19: ENGR1F-9Aim | E19: Preps | F19: 8 drama /MCCR2-3 -4S-a | G19: DAMR 2S, 3S,4S-a | H19: DTHR 2S,3S,4S-a | I19: MULTI - ELA 1,2,3,4 | J19: ENGR 2F- d | K19: 8 drama /MCCR2-3 -4S-a | L19: Preps
B20: Grunewald 215 | C20: HISR 3F-b | D20: Preps | E20: ENGC3S-b | F20: ENGR1F-9d | G20: ENGR1F-9e | H20: LAWR 4S-a | I20: SOSR1F-9b | J20: ENGR1F-9d | K20: Preps | L20: ENGR1F-9e
B21: Winger 135 | C21: TTBR4S-a RTBR3S-a CRPR2S-a | D21: HISR3F-a | E21: Preps | F21: PSYR4S-a | G21: CATT 2, 3, 4S zz | H21: TTBR4S-b RTBR3S-b CRPR2S-b | I21: GEOR2F-d | J21: PSYR4S-b | K21: Preps | L21: CATT 2, 3, 4S zz
B22: Carvalho 222 | C22: GEOR2F-a | D22: SOSR1F-9c | E22: SOSR1F-9d | F22: SCIR1F-9e | G22: Preps | H22: HISR3F-c | I22: SOSR1F-9a | J22: HISR 3F-d | K22: LWER1S-9d | L22: Preps
B23: Purdy | F23: ENGR1F-9b | K23: ENGR1F-9b
B24: Cousins | F24: ENGR1F-9a | K24: ENGR1F-9a
A25: Mendoza | B25: WORK ED
A26: Lockhart | B26: WORK ED
A27: Robbie | B27: WORK ED | D27: SOSR1F-9e | I27: LWER1S-9e
A28: LAL -1 | B28: LAL 234 | E28: ENBU 1,2,3G EANU 4G | J28: ENBU 1,2,3G EANU 4G
A29: Subject Area | B29: Teacher | C29: A | D29: B | E29: C | F29: D | G29: E | H29: A | I29: B | J29: C | K29: D | L29: E
D30: INSR3S CTSR4S ???? | I30: INSR3S CTSR4S ????
A31: Phys Ed (4) | B31: Baker Sr. Gym & 223 | C31: PHER2F a-b | D31: PHER1G-9a | E31: PHER3F-c | F31: Preps | G31: PHER4F-c | H31: PHER2F c-d | I31: PHER1G-9c | J31: Preps | K31: PHER1G-9e | L31: PHER3F-d
B32: Stewart Sr. Gym &135 | C32: PHER 2F - | D32: PHER 1G-9b | E32: Preps | F32: PHER4F-a | G32: PHER3F-b | H32: PHER2F- | I32: PHER1G-9d | J32: PHER4F--c | K32: Preps | L32: PHER4F-d
B33: Kubas* Sr. Gym & 223 | F33: Spec Ed PE PHER 1M- | K33: PHER3F-c
A34: The Arts –(2.5) | B34: Boyko* 159 | C34: VAHB1S-a/b | D34: 7 Art / preps | E34: VIAR2S-a | F34: 8 art / preps | G34: VIAR3S/4S-a | H34: VAHB1S-c/d | I34: 7 Art / preps | J34: VIAR3S/4S-b | K34: 8 art / preps | L34: VIAR2S-b
B35: Boville* 110 D-2,4,6 | C35: Noon hour Choir zz /MGUH 1S | D35: /MGUH 2-4S a MPIH 2-4S-a .5 | E35: (/DMTR1S-4S-a) OUT (Noon Hour Choir | F35: 7 band/ 8 choir | G35: Preps + TM | H35: DAHB1S (4A) D1,4,6 | I35: MGUH 2-4S b (2A) MPIH2-4S-b (2A) / | J35: MCCH 2-4S (2A)XXXXXXX | K35: 7 band/ 8 choir | L35: Noon hour Choir zz
B36: Sawatzky* 155 | C36: MCBR1S-a/ Sr. Jazz Band zz | D36: Int. Jazz Band zz | E36: Prepr | F36: 7&8 Fl Band | G36: MCBR2-4S-a/ Jr. Jazz Band zz | H36: MCBR1S-a/ Sr. Jazz Band zz | I36: Int. Jazz Band zz | J36: Prepr | K36: 7&8 Fl Band | L36: MCBR2-4S-a/ Jr. Jazz Band) zz
A37: IA/HE (5) | B37: Brugger* | C37: TDHR1S-a/ | D37: PRAY 7/ PRAY8 | E37: HOER2, 3, 4G-a* | F37: TADR2, 3,4S-a | G37: FSTR2-4S-a | H37: TDHR1S-b/ | I37: PRAY 7/ PRAY8 | J37: HOER2, 3, 4G-a* | K37: TADR2, 3,4S-b | L37: FSTR2, 3, 4S-b
B38: Didych* | C38: ELHR1G-a/PMHR1G-a | D38: PRAY 7/ PRAY8 | E38: Preps | F38: ELER2,3G,4S-a | G38: POMR2,3G,4S -a | H38: PMHR1G-b/c | I38: PRAY 7/ PRAY8 | J38: Preps | K38: POMR 2,3G,4S-b | L38: METR2,3G-4S -a
B39: Gomez* Changed FNUR 2G & 3G,4S | C39: FOHR1S-a/b | D39: PRAY 7/ PRAY8 | E39: Preps | F39: FNUR2S-a | G39: FNUR3G,4S-a | H39: FOHR1S -c/d | I39: PRAY 7/ PRAY8 | J39: Preps | K39: FNUR3G,4S-b | L39: FNUR2S-b
B40: Ostrowski* | C40: WOHR1G-a/ELHR1G b | D40: PRAY 7/ PRAY8 | E40: Preps | F40: WOOR2G-a | G40: WOOR3G,4S-a | H40: WOHR1G-b/c | I40: PRAY 7/ PRAY8 | J40: Preps/ | K40: WOOR 3G,4S-b | L40: WOOR2G-b
...

Sheet Master
D1: =SUM(D2:G2) -> 81 | H1: =SUM(H2:K2) -> 82
A2: counts | D2: =COUNTIF(D6:D126,"*"&$B$3&"*") -> 18 | E2: =COUNTIF(E6:E120,"*"&$B$3&"*") -> 19 | F2: =COUNTIF(F6:F120,"*"&$B$3&"*") -> 26 | G2: =COUNTIF(G6:G120,"*"&$B$3&"*") -> 18 | H2: =COUNTIF(H6:H120,"*"&$B$3&"*") -> 17 | I2: =COUNTIF(I6:I120,"*"&$B$3&"*") -> 19 | J2: =COUNTIF(J6:J120,"*"&$B$3&"*") -> 28 | K2: =COUNTIF(K6:K120,"*"&$B$3&"*") -> 18
A3: Highlight | B3: _1
B4: prep | D4: SEM 1 | H4: SEM 2
A5: Subject Area | B5: Teacher | C5: TEAM | D5: A | E5: B | F5: C | G5: D | H5: A2 | I5: B3 | J5: C4 | K5: D5
B6: Alfaro, Carl | C6: PE, FI, ELA | D6: ENGR_2F(02) | E6: ENGR_2F(04) | F6: PHEF_1F(02)C1 PHEF_1F(01)C2 | G6: PREP | H6: PHEF_2F(02) | I6: ENGR_2F(R1) | J6: PHEF_1F(02)C1 PHEF_1F(01)C2 | K6: PREP
B7: Alford, Darren | C7: Guidance | D7: PREP | E7: PREP | F7: PREP | G7: PREP | H7: PREP | I7: PREP | J7: PREP | K7: PREP
B8: Alibudbud, Bernard | C8: DM | D8: DM094V_2S(97) | E8: DM095V_3S(97) | F8: DM100V_4S(01) MP212V_4S(01) | G8: PREP | H8: DM101V_4S(01) MP214V_4S(01) | I8: PREP | J8: DM100V_4S(97) | K8: DM101V_4S(97)
B9: Anastasiadis, Mr. Dimitrios | C9: Admin | D9: PREP | E9: PREP | F9: PREP | G9: PREP | H9: PREP | I9: PREP | J9: PREP | K9: PREP
B10: Anis, Alora | C10: FI, FI Math | D10: MAPF_3S(01) | E10: PREP | F10: falf_3S(01) | G10: PSYF_4S(01) | H10: falf_3S(02) | I10: PREP | J10: falf_3S(03) | K10: MAPF_4S(01)
B11: Athayde, Melanie | C11: V/P, Sci | D11: PREP | E11: SCIS_2F(01) | F11: PREP | G11: DANR_4S(01) | H11: PREP | I11: DANR_2S(02) | J11: PREP | K11: DANR_4S(02)
B12: Bara, Myriam | C12: ISS | D12: PREP | E12: PREP | F12: PREP | G12: PREP | H12: PREP | I12: PREP | J12: PREP | K12: PREP
B13: Barnych, Dale | C13: PE | D13: PHER_4F(02)A1 PREP | E13: PREP PHER_1F(05)B2 | F13: PHER_2F(05) | G13: PHER_1F(14)D1 PHER_4F(06)D2 | H13: PREP | I13: PHER_4F(08)B1 PHER_1F(05)B2 | J13: PHER_2F(11) | K13: PHER_1F(14)D1 PHER_4F(11)D2
B14: Bazilewich, Charles | C14: CB | D14: CS109V_4S(01) | E14: CS105V_3S(01) | F14: CS106V_3S(01) | G14: PREP | H14: CS108V_4S(01) | I14: CS106V_3S(02) | J14: CS111V_4S(01) | K14: PREP
B15: Beckett, Patrick | C15: FI 9 | D15: falf_4S(01) | E15: falf_4S(02) | F15: PREP | G15: Fraf_2F(01) | H15: Fraf_2F(03) | I15: falf_4S(03) | J15: Fraf_2F(04) | K15: PREP
B16: Bilewitch, Curtis | C16: 9 SS | D16: RITR_1S(05) | E16: RITR_1S(07) | F16: SOSR_1F(05)C1 PREP | G16: PREP SOSR_1F(07)D2 | H16: ENGR_1F(05) | I16: ENGR_1F(07) | J16: SOSR_1F(05)C1 PREP | K16: PREP SOSR_1F(07)D2
B17: Boyes, Carolyn | C17: V/P | D17: PREP | E17: PREP | F17: MCCR_1S(01)C1 PREP | G17: PREP | H17: PREP | I17: PREP | J17: MCCR_1S(01)C1 PREP | K17: PREP
... B94: Tao, Shelly | C94: IA | D94: FNUR_3S(01) | E94: FNUR_3S(02) | F94: FOHR_1S(01)C1 PREP | G94: FNUR_4S(01) | H94: FNUR_2S(03) | I94: FNUR_3S(03) | J94: FOHR_1S(02)C1 PREP | K94: FNUR_4S(02)
B95: TEACHER V, Awa | C95: FI | D95: SCIF_1F(02) | E95: SCIF_2F(02) | F95: Fraf_2F(02) | G95: PREP
B96: Teacher X, Threadkell (Bernadette) | C96: FI | D96: HISF_3F(01) | E96: HISF_3F(02) | F96: PREP | G96: SCHF_1F(03) | H96: PREP | I96: SCHF_1F(01) | J96: HISF_3F(03) | K96: SCHF_1F(02)
B97: Teacher Y, PEP | C97: PEP | D97: ENGW_4S(01)A1 ENGW_3S(01)A2 | E97: HISW_3S(01)B1 GLIW_4S(01)B2 | F97: ENGW_2F(01)C1 PREPC2 | G97: PEP-Option_3(01)D1 PHEW_3F(01)D2 | H97: ENGW_4S(01)A1 ENGW_3S(01)A2 | I97: HISW_3S(01)B1 GLIW_4S(01)B2 | J97: ENGW_2F(01)C1 PREPC2 | K97: PEP-Option_3(01)D1 PE Support D2
B98: Teacher Z, PEP | C98: PEP | D98: ESMW_3S(01)A1 ESMW_4S(01)A2 | E98: INSW_4S(01)B1 CTSW_3S(01)B2 | F98: PEP-Option_3(02)C1 ESMW_2S(01)C2 | G98: PREPD1 PHEW_4F(01)D2 | H98: ESMW_3S(01)A1 ESMW_4S(01)A2 | I98: INSW_4S(01)B1 CTSW_3S(01)B2 | J98: PEP-Option_3(02)C1 ESMW_2S(01)C2 | K98: PREPD1 PE Support D2
B99: Thwaites, Mike | C99: V/P | D99: LWPR_2S(WE)A1 SCIW_2F(01)A2 | E99: PEP-Option_2(01) | F99: PrepC1 LWBR_3S(01)C2 | G99: PHEW_2F(01)D1 GEOW_2S(01)D2 | H99: LWPR_2S(WE)A1 SCIW_2F(01)A2 | I99: PEP-Option_2(01) | J99: PrepC1 LWBR_3S(01)C2 | K99: LWTF_4S(01)D1 GEOW_2S(01)D2
B100: Trethart, Andrew | C100: Sci | D100: PREP | E100: INSR_4S(01) | F100: ECPR_4S(01) | G100: BIOR_3S(02) | H100: BIOR_3S(04) | I100: BIOR_3S(05) | J100: BIOR_3S(06) | K100: PREP
B101: Truderung, Benita | C101: Sci, AP | D101: PH1P_4S(01) | E101: PHYE_3S(01) | F101: PREP | G101: PHYR_3S(02) | H101: PREP | I101: PHYE_4S(01) | J101: PHYR_3S(04) | K101: PHYR_4S(04)
B102: Villa, Carlos | C102: FI 9 | D102: FILF_1F(03) | E102: ENGF_1F(02) | F102: PREP | G102: FILF_1F(01) | H102: FILF_1F(02) | I102: ENGF_1F(03) | J102: PREP | K102: ENGF_1F(01)
B103: Waller, Aurora | C103: IA | D103: FSTR_3S(01) | E103: FSTR_4S(02) | F103: FSTR_3S(02) | G103: PREP | H103: FSTR_3S(03) | I103: PREP | J103: FSTR_4S(03) | K103: FSTR_4S(04)
B104: Wesley, Michelle | C104: ISS | D104: ENGC_3M(04)A1 ENGC_4M(02) ENGR_2M(03) ESMR_2M(04)A2 ESMR_3M(03) ESMR_4M(02) MATR_1M(05) | E104: RESR01(05) | F104: LWPR_2M(01)C1 PREP | G104: PREP LWER_1M(02)D2 LWPR_2M(02) | H104: PREP | I104: PREP | J104: PREP | K104: PREP
B105: Witzke, Jonathan | C105: PE, 9 | D105: PHER_1F(04)A1 PHER_1F(06)A2 | E105: PHER_1F(08)B1 PHER_3F(02)B2 | F105: PREP | G105: PHER_1F(07)D1 PHER_1F(12)D2 | H105: PHER_1F(04)A1 PHER_1F(06)A2 | I105: PHER_1F(08)B1 PHER_3F(08)B2 | J105: PREP | K105: PHER_1F(07)D1 PHER_1F(12)D2
B106: Wright, Kelly | C106: PEP | D106: LWPR_2S(WE)A1 SCIW_2F(01)A2 | E106: PEP-Option_2(01) | F106: PrepC1 LWBR_3S(01)C2 | G106: PHEW_2F(01)D1 GEOW_2S(01)D2 | H106: LWPR_2S(WE)A1 SCIW_2F(01)A2 | I106: PEP-Option_2(01) | J106: PrepC1 LWBR_3S(01)C2 | K106: LWTF_4S(01)D1 GEOW_2S(01)D2
B107: Yosyk, Lisa | C107: Math | D107: IAPE_2S(01) | E107: PREP | F107: PCME_3S(01) | G107: IAPR_2S(04) | H107: PCME_3S(02) | I107: PREP | J107: IAPR_2S(07) | K107: IAPR_2S(08)
... B109: Zurbuchen, Stephanie | C109: ELA, Sci | D109: ENGL_4S(02) | E109: PREP | F109: ENGC_4S(04) | G109: ENGL_3S(06) | H109: ENGL_4S(05) | I109: ENGR_2F(09) | J109: PREP | K109: CHER_3S(06)
B110: ZZ PLACE HOLDER | C110: Place holder

Sheet Code
A1: =Table1[[#Headers],[Teacher]] -> Teacher | B1: _S1_A_ | C1: _S1_B_ | D1: _S1_C_ | E1: _S1_D_ | F1: _S2_A_ | G1: _S2_B_ | H1: _S2_C_ | I1: _S2_D_
